Traceback (most recent call last):
  File "manage.py", line 22, in <module>
    main()
  File "manage.py", line 18, in main
    execute_from_command_line(sys.argv)
  File "/root/django/oxo/lib/python3.8/site-packages/django/core/management/__init__.py", line 419, in execute_from_command_line
    utility.execute()
  File "/root/django/oxo/lib/python3.8/site-packages/django/core/management/__init__.py", line 413, in execute
    self.fetch_command(subcommand).run_from_argv(self.argv)
  File "/root/django/oxo/lib/python3.8/site-packages/django/core/management/base.py", line 367, in run_from_argv
    connections.close_all()
  File "/root/django/oxo/lib/python3.8/site-packages/django/db/utils.py", line 208, in close_all
    for alias in self:
  File "/root/django/oxo/lib/python3.8/site-packages/django/utils/connection.py", line 73, in __iter__
    return iter(self.settings)
  File "/root/django/oxo/lib/python3.8/site-packages/django/utils/functional.py", line 48, in __get__
    res = instance.__dict__[self.name] = self.func(instance)
  File "/root/django/oxo/lib/python3.8/site-packages/django/utils/connection.py", line 45, in settings
    self._settings = self.configure_settings(self._settings)
  File "/root/django/oxo/lib/python3.8/site-packages/django/db/utils.py", line 144, in configure_settings
    databases = super().configure_settings(databases)
  File "/root/django/oxo/lib/python3.8/site-packages/django/utils/connection.py", line 50, in configure_settings
    settings = getattr(django_settings, self.settings_name)
  File "/root/django/oxo/lib/python3.8/site-packages/django/conf/__init__.py", line 82, in __getattr__
    self._setup(name)
  File "/root/django/oxo/lib/python3.8/site-packages/django/conf/__init__.py", line 69, in _setup
    self._wrapped = Settings(settings_module)
  File "/root/django/oxo/lib/python3.8/site-packages/django/conf/__init__.py", line 170, in __init__
    mod = importlib.import_module(self.SETTINGS_MODULE)
  File "/usr/lib/python3.8/importlib/__init__.py", line 127, in import_module
    return _bootstrap._gcd_import(name[level:], package, level)
  File "<frozen importlib._bootstrap>", line 1014, in _gcd_import
  File "<frozen importlib._bootstrap>", line 991, in _find_and_load
  File "<frozen importlib._bootstrap>", line 970, in _find_and_load_unlocked
ModuleNotFoundError: No module named 'blogproject.settings.local'; 'blogproject.settings' is not a package
[18/Nov/2021 19:31:11] "GET / HTTP/1.0" 200 6368
[18/Nov/2021 19:31:11] "GET /static/blog/js/script.jsj HTTP/1.0" 404 179
[18/Nov/2021 19:31:11] "GET /static/blog/js/script.jsj HTTP/1.0" 404 179
[18/Nov/2021 19:31:15] "GET / HTTP/1.0" 200 6368
[18/Nov/2021 19:31:15] "GET /static/blog/js/pace.min.js HTTP/1.0" 304 0
[18/Nov/2021 19:31:15] "GET /static/blog/js/modernizr.custom.js HTTP/1.0" 304 0
[18/Nov/2021 19:31:15] "GET /static/blog/js/script.jsj HTTP/1.0" 404 179
[18/Nov/2021 19:31:15] "GET /static/blog/js/script.jsj HTTP/1.0" 404 179
[18/Nov/2021 19:31:16] "GET / HTTP/1.0" 200 6368
[18/Nov/2021 19:31:16] "GET /static/blog/js/script.jsj HTTP/1.0" 404 179
[18/Nov/2021 19:31:17] "GET /static/blog/js/script.jsj HTTP/1.0" 404 179
[18/Nov/2021 19:34:43] "GET / HTTP/1.0" 200 6372
[18/Nov/2021 19:34:43] "GET /static/blog/js/script.jsj HTTP/1.0" 404 179
[18/Nov/2021 19:34:43] "GET /static/blog/js/script.jsj HTTP/1.0" 404 179
[18/Nov/2021 19:36:40] "GET / HTTP/1.0" 200 6372
[18/Nov/2021 19:36:40] "GET /static/blog/css/pace.css HTTP/1.0" 304 0
[18/Nov/2021 19:36:40] "GET /static/blog/css/custom.css HTTP/1.0" 304 0
[18/Nov/2021 19:36:40] "GET /static/blog/js/pace.min.js HTTP/1.0" 304 0
[18/Nov/2021 19:36:40] "GET /static/blog/js/script.jsj HTTP/1.0" 404 179
[18/Nov/2021 19:36:40] "GET /static/blog/js/modernizr.custom.js HTTP/1.0" 304 0
[18/Nov/2021 19:36:41] "GET /static/blog/js/script.jsj HTTP/1.0" 404 179
[18/Nov/2021 19:36:41] "GET /favicon.ico HTTP/1.0" 404 179
[18/Nov/2021 19:41:06] "GET / HTTP/1.0" 200 6386
[18/Nov/2021 19:41:06] "GET /static/blog/js/script.jsj HTTP/1.0" 404 179
[18/Nov/2021 19:41:07] "GET /static/blog/js/script.jsj HTTP/1.0" 404 179
[18/Nov/2021 19:41:08] "GET / HTTP/1.0" 200 6386
[18/Nov/2021 19:41:08] "GET /static/blog/css/pace.css HTTP/1.0" 304 0
[18/Nov/2021 19:41:08] "GET /static/blog/css/custom.css HTTP/1.0" 304 0
[18/Nov/2021 19:41:08] "GET /static/blog/js/pace.min.js HTTP/1.0" 304 0
[18/Nov/2021 19:41:08] "GET /static/blog/js/modernizr.custom.js HTTP/1.0" 304 0
[18/Nov/2021 19:41:08] "GET /static/blog/js/script.jsj HTTP/1.0" 404 179
[18/Nov/2021 19:41:08] "GET /static/blog/js/script.jsj HTTP/1.0" 404 179
[18/Nov/2021 19:42:03] "GET / HTTP/1.0" 200 6386
[18/Nov/2021 19:42:03] "GET /static/blog/js/script.jsj HTTP/1.0" 404 179
[18/Nov/2021 19:42:03] "GET /static/blog/js/script.jsj HTTP/1.0" 404 179
Exception in thread django-main-thread:
Traceback (most recent call last):
  File "/root/django/oxo/lib/python3.8/site-packages/pymysql/connections.py", line 613, in connect
    sock = socket.create_connection(
  File "/usr/lib/python3.8/socket.py", line 808, in create_connection
    raise err
  File "/usr/lib/python3.8/socket.py", line 796, in create_connection
    sock.connect(sa)
ConnectionRefusedError: [Errno 111] Connection refused

During handling of the above exception, another exception occurred:

Traceback (most recent call last):
  File "/root/django/oxo/lib/python3.8/site-packages/django/db/backends/base/base.py", line 219, in ensure_connection
    self.connect()
  File "/root/django/oxo/lib/python3.8/site-packages/django/utils/asyncio.py", line 33, in inner
    return func(*args, **kwargs)
  File "/root/django/oxo/lib/python3.8/site-packages/django/db/backends/base/base.py", line 200, in connect
    self.connection = self.get_new_connection(conn_params)
  File "/root/django/oxo/lib/python3.8/site-packages/django/utils/asyncio.py", line 33, in inner
    return func(*args, **kwargs)
  File "/root/django/oxo/lib/python3.8/site-packages/django/db/backends/mysql/base.py", line 234, in get_new_connection
    connection = Database.connect(**conn_params)
  File "/root/django/oxo/lib/python3.8/site-packages/pymysql/connections.py", line 353, in __init__
    self.connect()
  File "/root/django/oxo/lib/python3.8/site-packages/pymysql/connections.py", line 664, in connect
    raise exc
pymysql.err.OperationalError: (2003, "Can't connect to MySQL server on '127.0.0.1' ([Errno 111] Connection refused)")

The above exception was the direct cause of the following exception:

Traceback (most recent call last):
  File "/usr/lib/python3.8/threading.py", line 932, in _bootstrap_inner
    self.run()
  File "/usr/lib/python3.8/threading.py", line 870, in run
    self._target(*self._args, **self._kwargs)
  File "/root/django/oxo/lib/python3.8/site-packages/django/utils/autoreload.py", line 64, in wrapper
    fn(*args, **kwargs)
  File "/root/django/oxo/lib/python3.8/site-packages/django/core/management/commands/runserver.py", line 121, in inner_run
    self.check_migrations()
  File "/root/django/oxo/lib/python3.8/site-packages/django/core/management/base.py", line 486, in check_migrations
    executor = MigrationExecutor(connections[DEFAULT_DB_ALIAS])
  File "/root/django/oxo/lib/python3.8/site-packages/django/db/migrations/executor.py", line 18, in __init__
    self.loader = MigrationLoader(self.connection)
  File "/root/django/oxo/lib/python3.8/site-packages/django/db/migrations/loader.py", line 53, in __init__
    self.build_graph()
  File "/root/django/oxo/lib/python3.8/site-packages/django/db/migrations/loader.py", line 220, in build_graph
    self.applied_migrations = recorder.applied_migrations()
  File "/root/django/oxo/lib/python3.8/site-packages/django/db/migrations/recorder.py", line 77, in applied_migrations
    if self.has_table():
  File "/root/django/oxo/lib/python3.8/site-packages/django/db/migrations/recorder.py", line 55, in has_table
    with self.connection.cursor() as cursor:
  File "/root/django/oxo/lib/python3.8/site-packages/django/utils/asyncio.py", line 33, in inner
    return func(*args, **kwargs)
  File "/root/django/oxo/lib/python3.8/site-packages/django/db/backends/base/base.py", line 259, in cursor
    return self._cursor()
  File "/root/django/oxo/lib/python3.8/site-packages/django/db/backends/base/base.py", line 235, in _cursor
    self.ensure_connection()
  File "/root/django/oxo/lib/python3.8/site-packages/django/utils/asyncio.py", line 33, in inner
    return func(*args, **kwargs)
  File "/root/django/oxo/lib/python3.8/site-packages/django/db/backends/base/base.py", line 219, in ensure_connection
    self.connect()
  File "/root/django/oxo/lib/python3.8/site-packages/django/db/utils.py", line 90, in __exit__
    raise dj_exc_value.with_traceback(traceback) from exc_value
  File "/root/django/oxo/lib/python3.8/site-packages/django/db/backends/base/base.py", line 219, in ensure_connection
    self.connect()
  File "/root/django/oxo/lib/python3.8/site-packages/django/utils/asyncio.py", line 33, in inner
    return func(*args, **kwargs)
  File "/root/django/oxo/lib/python3.8/site-packages/django/db/backends/base/base.py", line 200, in connect
    self.connection = self.get_new_connection(conn_params)
  File "/root/django/oxo/lib/python3.8/site-packages/django/utils/asyncio.py", line 33, in inner
    return func(*args, **kwargs)
  File "/root/django/oxo/lib/python3.8/site-packages/django/db/backends/mysql/base.py", line 234, in get_new_connection
    connection = Database.connect(**conn_params)
  File "/root/django/oxo/lib/python3.8/site-packages/pymysql/connections.py", line 353, in __init__
    self.connect()
  File "/root/django/oxo/lib/python3.8/site-packages/pymysql/connections.py", line 664, in connect
    raise exc
django.db.utils.OperationalError: (2003, "Can't connect to MySQL server on '127.0.0.1' ([Errno 111] Connection refused)")
[20/Nov/2021 12:11:46] "GET / HTTP/1.0" 200 6386
[20/Nov/2021 12:11:47] "GET /static/blog/css/pace.css HTTP/1.0" 304 0
[20/Nov/2021 12:11:47] "GET /static/blog/js/script.jsj HTTP/1.0" 404 179
[20/Nov/2021 12:11:47] "GET /static/blog/css/custom.css HTTP/1.0" 304 0
[20/Nov/2021 12:11:47] "GET /static/blog/js/pace.min.js HTTP/1.0" 304 0
[20/Nov/2021 12:11:47] "GET /static/blog/js/modernizr.custom.js HTTP/1.0" 304 0
[20/Nov/2021 12:11:47] "GET /static/blog/js/script.jsj HTTP/1.0" 404 179
[20/Nov/2021 12:12:30] "GET / HTTP/1.0" 200 6386
[20/Nov/2021 12:19:04] "GET / HTTP/1.0" 200 6386
[20/Nov/2021 12:19:07] "GET /static/blog/js/modernizr.custom.js HTTP/1.0" 304 0
[20/Nov/2021 12:19:07] "GET /static/blog/js/pace.min.js HTTP/1.0" 304 0
[20/Nov/2021 12:19:07] "GET /static/blog/js/script.jsj HTTP/1.0" 404 179
[20/Nov/2021 12:19:15] "GET / HTTP/1.0" 200 6386
[20/Nov/2021 12:19:32] "GET /admin/ HTTP/1.0" 302 0
[20/Nov/2021 12:19:32] "GET /static/blog/js/script.jsj HTTP/1.0" 404 179
[20/Nov/2021 12:19:36] "GET /admin/login/?next=/admin/ HTTP/1.0" 200 2216
[20/Nov/2021 12:19:37] "GET /static/admin/css/base.css HTTP/1.0" 304 0
[20/Nov/2021 12:19:37] "GET /static/admin/css/responsive.css HTTP/1.0" 304 0
[20/Nov/2021 12:19:37] "GET /static/admin/css/nav_sidebar.css HTTP/1.0" 304 0
[20/Nov/2021 12:19:37] "GET /static/admin/css/login.css HTTP/1.0" 304 0
[20/Nov/2021 12:19:37] "GET /static/admin/js/nav_sidebar.js HTTP/1.0" 304 0
[20/Nov/2021 12:19:39] "GET /static/admin/css/fonts.css HTTP/1.0" 304 0
[20/Nov/2021 12:19:41] "GET /static/admin/fonts/Roboto-Light-webfont.woff HTTP/1.0" 304 0
[20/Nov/2021 12:19:41] "GET /static/admin/fonts/Roboto-Regular-webfont.woff HTTP/1.0" 304 0
[20/Nov/2021 12:22:38] "POST /admin/login/?next=/admin/ HTTP/1.0" 302 0
[20/Nov/2021 12:22:40] "GET /admin/ HTTP/1.0" 200 5414
[20/Nov/2021 12:22:51] "GET /static/admin/css/dashboard.css HTTP/1.0" 304 0
[20/Nov/2021 12:22:53] "GET /static/admin/img/icon-changelink.svg HTTP/1.0" 304 0
[20/Nov/2021 12:22:55] "GET /static/admin/fonts/Roboto-Bold-webfont.woff HTTP/1.0" 304 0
[20/Nov/2021 12:22:56] "GET /static/admin/img/icon-addlink.svg HTTP/1.0" 304 0
[20/Nov/2021 12:22:58] "GET /admin/login/?next=/admin/ HTTP/1.0" 302 0
[20/Nov/2021 12:22:59] "GET /admin/login/?next=/admin/ HTTP/1.0" 302 0
[20/Nov/2021 12:23:03] "GET /admin/ HTTP/1.0" 200 5414
